Workbook

Sheet Summary
A1: خطة تطوير منصة GRC — مصرف ليبيا الإسلامي
A2: ناتج مقارنة المنصة الحالية بعروض الموردين الستة والممارسات الدولية/الإقليمية
A4: إجمالي بنود التطوير | B4: =COUNTA(Backlog!A2:A44)
A5: بنود P0 (حرجة) | B5: =COUNTIF(Backlog!G2:G44,"P0")
A6: بنود P1 | B6: =COUNTIF(Backlog!G2:G44,"P1")
A7: بنود P2 | B7: =COUNTIF(Backlog!G2:G44,"P2")
A8: بنود P3 | B8: =COUNTIF(Backlog!G2:G44,"P3")
A9: إجمالي الجهد التقديري (أيام عمل) | B9: =SUM(Backlog!H2:H44)
A10: الإصدار 1 (أيام) | B10: =SUMIF(Backlog!B2:B44,"R1",Backlog!H2:H44)
A11: الإصدار 2 (أيام) | B11: =SUMIF(Backlog!B2:B44,"R2",Backlog!H2:H44)
A12: الإصدار 3 (أيام) | B12: =SUMIF(Backlog!B2:B44,"R3",Backlog!H2:H44)
A13: الإصدار 4 (أيام) | B13: =SUMIF(Backlog!B2:B44,"R4",Backlog!H2:H44)
A14: غير وظيفي (أيام) | B14: =SUMIF(Backlog!B2:B44,"NF",Backlog!H2:H44)
A15: بنود تحتاج بريداً/SMTP | B15: =COUNTIF(Backlog!J2:J44,"smtp")
A16: بنود تحتاج cron | B16: =COUNTIF(Backlog!J2:J44,"cron")
A17: بنود تحتاج بنية غير الاستضافة المشتركة | B17: =COUNTIF(Backlog!J2:J44,"infra")
A18: قدرات منفّذة بالكامل لدينا | B18: =COUNTIF('Capability matrix'!D2:D47,2)
A19: قدرات جزئية | B19: =COUNTIF('Capability matrix'!D2:D47,1)
A20: قدرات غير موجودة | B20: =COUNTIF('Capability matrix'!D2:D47,0)
A21: خطوات POC مغطاة كلياً | B21: ='POC check'!D20
A22: خطوات POC جزئية | B22: ='POC check'!D21
A23: خطوات POC مفقودة | B23: ='POC check'!D22
A25: ملاحظات للقراءة:
A26: • التقدير بأيام عمل مطوّر واحد كمرتبة أولية (±50%) دون اختبارات قبول المصرف ولا إدارة المشروع.
A27: • ترتيب الإصدارات توصية؛ للجنة تعديلها بحسب الاستراتيجية.
A28: • عمود «الاستضافة»: ok = يعمل على الاستضافة المشتركة، cron/smtp = يتطلب مهمة مجدولة أو بريداً، infra = يتطلب بنية أو مسار شبكة خارج الاستضافة المشتركة.
A29: • لم تُتحقق ادعاءات الموردين مستقلاً، ولم أتمكن من فتح موقع مصرف ليبيا المركزي.

Sheet Backlog
A1: ID | B1: الإصدار | C1: المحور | D1: العنوان | E1: Title | F1: الوصف | G1: الأولوية | H1: التقدير (أيام عمل) | I1: يعتمد على | J1: الاستضافة | K1: معيار القبول | L1: الأساس
A2: GRC-001 | B2: R1 | C2: الضوابط | D2: مكتبة ضوابط مركزية | E2: Central control library | F2: كيان ضابط مستقل (رمز، وصف، تصنيف، مالك، تكرار، آلي/يدوي، رئيسي/ثانوي) وربط متعدد لمتعدد مع المخاطر. | G2: P0 | H2: 15 | I2: - | J2: ok | K2: إنشاء ضابط وربطه بعدة مخاطر وبالعكس؛ تصفية بالتصنيف؛ يظهر في صفحة الخطر وسجل التغييرات. | L2: تصنيف السوق/Basel PSMOR
A3: GRC-002 | B3: R1 | C3: الضوابط | D3: اختبار الضوابط وبرامج الفحص | E3: Control testing programs | F3: برامج اختبار (تصميم/تشغيل)، قوائم تحقق، عينات، جدولة، مختبِر مستقل عن مالك الضابط، دليل إلزامي لتقييم «فعّال». | G3: P0 | H3: 25 | I3: GRC-001 | J3: cron | K3: لا يمكن تقييم ضابط فعّالاً بلا دليل؛ فجوة الضابط تنشئ إجراءً؛ سجل نتائج بالتاريخ. | L3: فجوة مقارنة العروض
A4: GRC-003 | B4: R1 | C4: الضوابط | D4: الخطر المتبقي المقترح من نتائج الاختبار | E4: Test-informed residual suggestion | F4: عرض قيمة متبقية مقترحة مشتقة من فعالية الضوابط بجانب التقييم الصريح مع تنبيه عند التعارض (دون خصم تلقائي). | G4: P1 | H4: 8 | I4: GRC-002 | J4: ok | K4: تظهر المقارنة (صريح/مقترح) وتُطلب مبررات عند الفرق الكبير. | L4: قرار التصميم الحالي
A5: GRC-004 | B5: R1 | C5: سير العمل | D5: محرك موافقات (Maker/Checker) على السجلات | E5: Approval workflow engine | F5: مسار إعداد←مراجعة←اعتماد قابل للتهيئة لكل نوع سجل (خطر، حادث، التزام، سياسة، مؤشر)، مع منع نفس المستخدم من الإعداد والاعتماد. | G5: P0 | H5: 25 | I5: - | J5: ok | K5: تفعيل المسار لنوع سجل واحد على الأقل دون تعديل كود؛ لا يُغلق سجل قبل الاعتماد؛ مسجّل في التدقيق. | L5: Maker/Checker لدى كل العروض
A6: GRC-005 | B6: R1 | C6: سير العمل | D6: الإشعارات بالبريد والتصعيد التلقائي | E6: Email notifications and auto-escalation | F6: إعداد SMTP، قوالب ثنائية اللغة، تذكير بالمواعيد، تصعيد المتأخر حسب مصفوفة، يعمل بمهمة cron واحدة في cPanel. | G6: P0 | H6: 15 | I6: - | J6: smtp | K6: إرسال تذكير قبل الموعد وتصعيد بعده؛ سجل إرسال؛ إيقاف/تفعيل لكل مستخدم. | L6: تنبيهات لدى كل العروض
A7: GRC-006 | B7: R1 | C7: سير العمل | D7: صفحة «مهامي» والتقويم | E7: My tasks and calendar | F7: قائمة موحدة لما يخص المستخدم: إجراءات، مراجعات، قراءات KRI، اختبارات ضوابط، التزامات، تقييمات ذاتية، مع عرض تقويم. | G7: P1 | H7: 10 | I7: - | J7: ok | K7: تعرض كل المهام المفتوحة للمستخدم مرتبة بالموعد ومع روابط مباشرة. | L7: تجربة مستخدم السوق
A8: GRC-007 | B8: R1 | C8: التقارير | D8: تصدير XLSX وPDF أصلي وحزمة تقرير المجلس | E8: Native XLSX/PDF export and board pack | F8: تصدير Excel حقيقي وPDF للتقارير وحزمة دورية (لوحة، أعلى المخاطر، الخسائر، KRIs، المتأخرات) بالعربية RTL. | G8: P0 | H8: 12 | I8: - | J8: ok | K8: ملف PDF عربي سليم؛ XLSX يحافظ على العربية والأرقام؛ بنفس صلاحيات الشاشة. | L8: اختبار POC
A9: GRC-008 | B9: R1 | C9: المؤشرات | D9: KRIs متقدمة | E9: Advanced KRIs | F9: 4 مستويات حدود، مصدر بيانات (يدوي/استيراد/API)، بوابة جودة بيانات، علامة «متأخر»، سجل خرق مع مبررات وتصعيد، مؤشرات مركبة، مراجعة دورية للمؤشر. | G9: P1 | H9: 20 | I9: GRC-004,GRC-005 | J9: cron | K9: خرق حرج يفتح سجل خرق ويُصعَّد؛ لا يُنشر مؤشر قبل التحقق؛ مؤشر مركب بمعادلة معتمدة. | L9: تحسين مقارنة العروض
A10: GRC-009 | B10: R1 | C10: الأحداث | D10: تصنيف Basel وخطوط الأعمال والمستردات حسب المصدر | E10: Basel taxonomy, recovery sources, non-financial impact | F10: تصنيف أحداث Basel، خط عمل، منتج، نظام، مصادر استرداد (تأمين/عميل/موظف/مورد)، الأثر غير المالي، أنواع الحدث (فعلي، شبه، ربح، محتمل، مسترد كلياً). | G10: P1 | H10: 15 | I10: - | J10: ok | K10: حقول إلزامية قابلة للتهيئة؛ تقرير خسائر حسب نوع Basel وخط العمل. | L10: Basel / SMA
A11: GRC-010 | B11: R1 | C11: الأحداث | D11: عتبات التسجيل والتصعيد وبوابات الإغلاق وكشف التكرار | E11: Thresholds, closure gates, recurrence detection | F11: عتبات مالية للتصعيد، بوابة إغلاق (سبب جذري، قيمة مؤكدة، إجراءات معتمدة)، اقتراح تجميع الأحداث المتشابهة، وإطلاق إعادة تقييم الخطر. | G11: P1 | H11: 12 | I11: GRC-004,GRC-005 | J11: ok | K11: حادث فوق العتبة يُصعَّد تلقائياً؛ لا إغلاق دون استيفاء البوابة؛ اقتراح أنماط بقاعدة بسيطة. | L11: عروض متعددة
A12: GRC-011 | B12: R1 | C12: القابلية | D12: مصفوفة صلاحيات قبول الخطر وفحص اتساق الحدود | E12: Risk acceptance authority matrix | F12: قبول الخطر المتبقي المتجاوز للحد يتطلب مستوى صلاحية محدداً؛ فحص اتساق حدود KRI مع القابلية. | G12: P1 | H12: 10 | I12: GRC-004 | J12: ok | K12: قبول بدون الصلاحية مرفوض؛ تقرير بالمخاطر المقبولة وصلاحياتها. | L12: ISO 31000/COSO
A13: GRC-012 | B13: R1 | C13: RCSA | D13: دورات RCSA مجدولة وإعادة التقييم المحفّز | E13: Scheduled RCSA cycles and triggers | F13: جدولة سنوية/حسب الأهمية وإطلاق تلقائي، ومحفّزات (حادث جسيم، فشل ضابط رئيسي، منتج جديد، تغيير نظام/لائحة). | G13: P1 | H13: 12 | I13: GRC-005 | J13: cron | K13: تُطلق تقييمات الدورة تلقائياً؛ حادث جسيم يقترح إعادة تقييم للخطر المرتبط. | L13: Basel PSMOR (إدارة التغيير)
... A44: GRC-043 | B44: NF | C44: التوطين | D44: مراجعة لغوية متخصصة للواجهة العربية | E44: Arabic wording review | F44: مراجعة المصطلحات المصرفية/الشرعية من متخصص قبل الإنتاج. | G44: P1 | H44: 5 | I44: - | J44: ok | K44: قاموس مصطلحات معتمد ومطبّق. | L44: جودة

Sheet Capability matrix
A1: المحور | B1: القدرة | C1: Capability | D1: منصتنا | E1: FOCUS GRC | F1: Rabbit-Hole | G1: SHIRA | H1: Shamil | I1: OneSumX | J1: Ocean/ITS | K1: عدد العروض التي تغطي بالكامل | L1: الفجوة؟ | M1: ملاحظات
A2: الأساس: المخاطر التشغيلية | B2: سجل المخاطر (أسباب، عواقب، مالك، تواريخ) | C2: Risk register | D2: 2 | E2: 2 | F2: 2 | G2: 2 | H2: 2 | I2: 2 | J2: 0 | K2: =COUNTIF(E2:J2,2) | L2: =IF(D2=2,"لا",IF(K2>=1,"نعم","نعم (ريادة محتملة)"))
A3: الأساس: المخاطر التشغيلية | B3: مصفوفة تقييم قابلة للتهيئة (أصلي/متبقٍ) | C3: Configurable inherent/residual matrix | D3: 2 | E3: 2 | F3: 2 | G3: 2 | H3: 2 | I3: 2 | J3: 1 | K3: =COUNTIF(E3:J3,2) | L3: =IF(D3=2,"لا",IF(K3>=1,"نعم","نعم (ريادة محتملة)")) | M3: لدينا: 5×5 قابلة للتهيئة مع حدود مالية وفئات
A4: الأساس: المخاطر التشغيلية | B4: مكتبة ضوابط مركزية وربط خطر↔ضابط (متعدد لمتعدد) | C4: Central control library, many-to-many risk-control mapping | D4: 1 | E4: 2 | F4: 1 | G4: 2 | H4: 2 | I4: 2 | J4: 0 | K4: =COUNTIF(E4:J4,2) | L4: =IF(D4=2,"لا",IF(K4>=1,"نعم","نعم (ريادة محتملة)")) | M4: لدينا: وصف ضوابط نصي ومالك وتقييم يدوي لكل خطر فقط
A5: الأساس: المخاطر التشغيلية | B5: تصنيف الضوابط (وقائي/كشفي/تصحيحي، رئيسي/ثانوي، آلي/يدوي، دوري) | C5: Control classification | D5: 0 | E5: 0 | F5: 1 | G5: 2 | H5: 2 | I5: 2 | J5: 0 | K5: =COUNTIF(E5:J5,2) | L5: =IF(D5=2,"لا",IF(K5>=1,"نعم","نعم (ريادة محتملة)"))
A6: الأساس: المخاطر التشغيلية | B6: اختبار الضوابط (تصميم/تشغيل، قوائم تحقق، عينات، جدولة، أدلة) | C6: Control testing (design/operating, checklists, sampling, scheduling) | D6: 0 | E6: 2 | F6: 1 | G6: 2 | H6: 2 | I6: 2 | J6: 0 | K6: =COUNTIF(E6:J6,2) | L6: =IF(D6=2,"لا",IF(K6>=1,"نعم","نعم (ريادة محتملة)")) | M6: أكبر فجوة وظيفية لدينا مقابل جميع العروض
A7: الأساس: المخاطر التشغيلية | B7: حساب الخطر المتبقي المستند إلى نتائج اختبار الضوابط | C7: Residual risk informed by control-test results | D7: 0 | E7: 1 | F7: 1 | G7: 2 | H7: 2 | I7: 2 | J7: 0 | K7: =COUNTIF(E7:J7,2) | L7: =IF(D7=2,"لا",IF(K7>=1,"نعم","نعم (ريادة محتملة)")) | M7: قرار تصميم: لدينا المتبقي صريح بلا خصم تلقائي؛ المقترح: قيمة مقترحة بجانب التقييم الصريح
A8: الأساس: المخاطر التشغيلية | B8: RCSA: استبيانات ومراجعة واعتماد | C8: RCSA questionnaires and review workflow | D8: 2 | E8: 2 | F8: 2 | G8: 2 | H8: 2 | I8: 2 | J8: 1 | K8: =COUNTIF(E8:J8,2) | L8: =IF(D8=2,"لا",IF(K8>=1,"نعم","نعم (ريادة محتملة)"))
A9: الأساس: المخاطر التشغيلية | B9: جدولة دورات RCSA وإعادة التقييم المحفّز بالأحداث | C9: Scheduled RCSA cycles, event-triggered reassessment | D9: 0 | E9: 1 | F9: 2 | G9: 2 | H9: 2 | I9: 1 | J9: 0 | K9: =COUNTIF(E9:J9,2) | L9: =IF(D9=2,"لا",IF(K9>=1,"نعم","نعم (ريادة محتملة)"))
A10: الأساس: المخاطر التشغيلية | B10: خطط المعالجة (مسؤول، موعد، حالة) | C10: Treatment/action plans | D10: 2 | E10: 2 | F10: 2 | G10: 2 | H10: 2 | I10: 2 | J10: 2 | K10: =COUNTIF(E10:J10,2) | L10: =IF(D10=2,"لا",IF(K10>=1,"نعم","نعم (ريادة محتملة)"))
A11: الأساس: المخاطر التشغيلية | B11: قبول الخطر بصلاحيات مرتبطة بالقابلية للمخاطر | C11: Risk acceptance with authority levels | D11: 1 | E11: 1 | F11: 1 | G11: 2 | H11: 2 | I11: 1 | J11: 1 | K11: =COUNTIF(E11:J11,2) | L11: =IF(D11=2,"لا",IF(K11>=1,"نعم","نعم (ريادة محتملة)")) | M11: لدينا: قبول تجاوز بملاحظة إلزامية بلا مصفوفة صلاحيات
A12: الأساس: المخاطر التشغيلية | B12: بيانات قابلية تحمل المخاطر ومتابعة التجاوزات | C12: Risk appetite statements and breach tracking | D12: 2 | E12: 1 | F12: 2 | G12: 2 | H12: 2 | I12: 1 | J12: 1 | K12: =COUNTIF(E12:J12,2) | L12: =IF(D12=2,"لا",IF(K12>=1,"نعم","نعم (ريادة محتملة)"))
A13: الأحداث والخسائر | B13: تسجيل الحوادث وشبه الحوادث (إجمالي/مستردات/صافي) | C13: Loss events and near misses | D13: 2 | E13: 2 | F13: 2 | G13: 2 | H13: 2 | I13: 2 | J13: 1 | K13: =COUNTIF(E13:J13,2) | L13: =IF(D13=2,"لا",IF(K13>=1,"نعم","نعم (ريادة محتملة)"))
A14: الأحداث والخسائر | B14: تصنيف أحداث Basel وخطوط الأعمال | C14: Basel event-type and business-line taxonomy | D14: 0 | E14: 1 | F14: 1 | G14: 1 | H14: 2 | I14: 2 | J14: 0 | K14: =COUNTIF(E14:J14,2) | L14: =IF(D14=2,"لا",IF(K14>=1,"نعم","نعم (ريادة محتملة)"))
A15: الأحداث والخسائر | B15: المستردات حسب المصدر، الأثر غير المالي، التسوية مع الأستاذ العام، عتبات التصعيد | C15: Recovery by source, non-financial impact, GL reconciliation, escalation thresholds | D15: 0 | E15: 1 | F15: 1 | G15: 1 | H15: 2 | I15: 2 | J15: 0 | K15: =COUNTIF(E15:J15,2) | L15: =IF(D15=2,"لا",IF(K15>=1,"نعم","نعم (ريادة محتملة)"))
A16: الأحداث والخسائر | B16: ربط الحدث بإعادة تقييم الخطر وكشف التكرار/الأنماط | C16: Incident-to-risk reassessment, recurrence detection | D16: 1 | E16: 2 | F16: 1 | G16: 2 | H16: 2 | I16: 2 | J16: 0 | K16: =COUNTIF(E16:J16,2) | L16: =IF(D16=2,"لا",IF(K16>=1,"نعم","نعم (ريادة محتملة)")) | M16: لدينا: ربط حدث↔خطر فقط
A17: مؤشرات المخاطر | B17: KRIs: حدود، دورية، تنبيهات على الشاشة | C17: KRIs with thresholds and frequency | D17: 2 | E17: 2 | F17: 2 | G17: 2 | H17: 2 | I17: 2 | J17: 1 | K17: =COUNTIF(E17:J17,2) | L17: =IF(D17=2,"لا",IF(K17>=1,"نعم","نعم (ريادة محتملة)"))
A18: مؤشرات المخاطر | B18: KRIs متقدمة: 4 مستويات، تغذية آلية، بوابة جودة بيانات، مؤشرات مركبة، سجل خرق | C18: Advanced KRIs: multi-band, feeds, data-quality gate, composite, breach record | D18: 0 | E18: 1 | F18: 1 | G18: 1 | H18: 2 | I18: 1 | J18: 0 | K18: =COUNTIF(E18:J18,2) | L18: =IF(D18=2,"لا",IF(K18>=1,"نعم","نعم (ريادة محتملة)"))
A19: الاستمرارية والمرونة | B19: تحليل الأثر على الأعمال وأهداف التعافي (RTO/RPO/MTPD) | C19: BIA and recovery objectives | D19: 0 | E19: 2 | F19: 1 | G19: 2 | H19: 2 | I19: 0 | J19: 2 | K19: =COUNTIF(E19:J19,2) | L19: =IF(D19=2,"لا",IF(K19>=1,"نعم","نعم (ريادة محتملة)")) | M19: مقترح Rabbit-Hole يذكر أن وحدة BCM قيد البناء (ص16)
A20: الاستمرارية والمرونة | B20: خطط الاستمرارية، الاختبارات والتمارين، سجل الأزمة، شجرة الاتصال، الإشعار الطارئ | C20: BCP, testing, crisis log, call tree, emergency notification | D20: 0 | E20: 2 | F20: 1 | G20: 1 | H20: 2 | I20: 0 | J20: 2 | K20: =COUNTIF(E20:J20,2) | L20: =IF(D20=2,"لا",IF(K20>=1,"نعم","نعم (ريادة محتملة)"))
A21: الامتثال والحوكمة | B21: سجل التعليمات والتعاميم الرقابية وتوزيعها والمراسلات | C21: Regulatory instruction/circular register, distribution, correspondence | D21: 1 | E21: 2 | F21: 2 | G21: 2 | H21: 0 | I21: 1 | J21: 1 | K21: =COUNTIF(E21:J21,2) | L21: =IF(D21=2,"لا",IF(K21>=1,"نعم","نعم (ريادة محتملة)")) | M21: لدينا: سجل التزامات بمسؤول وموعد وأدلة، دون سجل تعاميم
A22: الامتثال والحوكمة | B22: فحوصات الامتثال الدورية ومؤشرات الامتثال | C22: Periodic compliance tests and compliance KPIs | D22: 0 | E22: 2 | F22: 2 | G22: 2 | H22: 0 | I22: 1 | J22: 1 | K22: =COUNTIF(E22:J22,2) | L22: =IF(D22=2,"لا",IF(K22>=1,"نعم","نعم (ريادة محتملة)"))
A23: الامتثال والحوكمة | B23: دورة حياة الوثائق والسياسات (اعتماد، إقرار الاطلاع) | C23: Policy lifecycle with approval and attestation | D23: 1 | E23: 2 | F23: 2 | G23: 2 | H23: 0 | I23: 0 | J23: 1 | K23: =COUNTIF(E23:J23,2) | L23: =IF(D23=2,"لا",IF(K23>=1,"نعم","نعم (ريادة محتملة)")) | M23: لدينا: إصدارات غير قابلة للتعديل دون مسار اعتماد
A24: الامتثال والحوكمة | B24: حوكمة المجلس واللجان: التشكيل، الاجتماعات، المحاضر، الحضور، التقييم، فحص الالتزام بتعليمات المصرف المركزي | C24: Board/committee governance incl. meetings, minutes, attendance, evaluation | D24: 1 | E24: 2 | F24: 0 | G24: 2 | H24: 0 | I24: 1 | J24: 1 | K24: =COUNTIF(E24:J24,2) | L24: =IF(D24=2,"لا",IF(K24>=1,"نعم","نعم (ريادة محتملة)")) | M24: لدينا: قرارات اللجان ومتابعتها فقط
A25: الامتثال والحوكمة | B25: الأهداف الاستراتيجية وبطاقات الأداء المتوازن ومؤشرات الأداء | C25: Strategic objectives, balanced scorecard, KPIs | D25: 0 | E25: 0 | F25: 0 | G25: 2 | H25: 0 | I25: 0 | J25: 0 | K25: =COUNTIF(E25:J25,2) | L25: =IF(D25=2,"لا",IF(K25>=1,"نعم","نعم (ريادة محتملة)"))
A26: الامتثال والحوكمة | B26: هيكل تنظيمي متعدد المستويات وخطوط الدفاع الثلاثة | C26: Multi-level org hierarchy, three lines of defence | D26: 1 | E26: 2 | F26: 1 | G26: 2 | H26: 2 | I26: 2 | J26: 1 | K26: =COUNTIF(E26:J26,2) | L26: =IF(D26=2,"لا",IF(K26>=1,"نعم","نعم (ريادة محتملة)")) | M26: لدينا: إدارات وفروع بمستوى واحد
A27: الامتثال والحوكمة | B27: مكتبة العمليات والمنتجات والخدمات والأصول وربطها بالمخاطر | C27: Process/product/service/asset libraries linked to risks | D27: 0 | E27: 1 | F27: 1 | G27: 2 | H27: 2 | I27: 2 | J27: 2 | K27: =COUNTIF(E27:J27,2) | L27: =IF(D27=2,"لا",IF(K27>=1,"نعم","نعم (ريادة محتملة)"))
A28: الامتثال والحوكمة | B28: التدقيق الداخلي المبني على المخاطر | C28: Risk-based internal audit | D28: 0 | E28: 2 | F28: 1 | G28: 1 | H28: 0 | I28: 0 | J28: 0 | K28: =COUNTIF(E28:J28,2) | L28: =IF(D28=2,"لا",IF(K28>=1,"نعم","نعم (ريادة محتملة)")) | M28: منتج منفصل لدى بعض الموردين
A29: الامتثال والحوكمة | B29: مخاطر الأطراف الثالثة والتعهيد | C29: Third-party / outsourcing risk | D29: 0 | E29: 0 | F29: 0 | G29: 1 | H29: 1 | I29: 0 | J29: 2 | K29: =COUNTIF(E29:J29,2) | L29: =IF(D29=2,"لا",IF(K29>=1,"نعم","نعم (ريادة محتملة)"))
A30: الامتثال والحوكمة | B30: مخاطر تقنية المعلومات والأمن السيبراني (ISO 27001/27005، تصنيف الأصول) | C30: IT/cyber risk, ISO 27001 mapping, asset classification | D30: 0 | E30: 1 | F30: 0 | G30: 1 | H30: 0 | I30: 0 | J30: 2 | K30: =COUNTIF(E30:J30,2) | L30: =IF(D30=2,"لا",IF(K30>=1,"نعم","نعم (ريادة محتملة)"))
A31: الامتثال والحوكمة | B31: المخاطر البيئية والاجتماعية والحوكمة (ESG) | C31: ESG risk | D31: 0 | E31: 0 | F31: 0 | G31: 2 | H31: 2 | I31: 0 | J31: 0 | K31: =COUNTIF(E31:J31,2) | L31: =IF(D31=2,"لا",IF(K31>=1,"نعم","نعم (ريادة محتملة)"))
A32: الامتثال والحوكمة | B32: اختبارات الضغط وكفاية رأس المال (ICAAP) | C32: Stress testing / ICAAP | D32: 0 | E32: 0 | F32: 0 | G32: 1 | H32: 0 | I32: 0 | J32: 0 | K32: =COUNTIF(E32:J32,2) | L32: =IF(D32=2,"لا",IF(K32>=1,"نعم","نعم (ريادة محتملة)")) | M32: اختياري لدى SHIRA
A33: الصيرفة الإسلامية | B33: فئات مخاطر إسلامية قابلة للتهيئة | C33: Configurable Islamic risk categories | D33: 2 | E33: 0 | F33: 0 | G33: 1 | H33: 0 | I33: 0 | J33: 0 | K33: =COUNTIF(E33:J33,2) | L33: =IF(D33=2,"لا",IF(K33>=1,"نعم","نعم (ريادة محتملة)")) | M33: لم يصف أي عرض سير عمل شرعياً مخصصاً؛ SHIRA يذكر الانسجام مع AAOIFI
A34: الصيرفة الإسلامية | B34: وحدة امتثال شرعي (سجل قرارات/فتاوى، مراجعة شرعية، أحداث عدم التزام، تطهير الدخل المحرّم) | C34: Sharia compliance workflow (rulings register, review, non-compliance events, purification) | D34: 1 | E34: 0 | F34: 0 | G34: 0 | H34: 0 | I34: 0 | J34: 0 | K34: =COUNTIF(E34:J34,2) | L34: =IF(D34=2,"لا",IF(K34>=1,"نعم","نعم (ريادة محتملة)")) | M34: لدينا: فئات + لجنة هيئة رقابة شرعية ضمن قرارات اللجان. فرصة تميّز: لا يغطيها أي عرض
A35: المنصة والأمن | B35: واجهة عربية/إنجليزية RTL/LTR | C35: Bilingual RTL/LTR UI | D35: 2 | E35: 2 | F35: 2 | G35: 2 | H35: 1 | I35: 1 | J35: 0 | K35: =COUNTIF(E35:J35,2) | L35: =IF(D35=2,"لا",IF(K35>=1,"نعم","نعم (ريادة محتملة)")) | M35: تقييم اللجنة لـShamil "محدود" بينما عرضه الفني يذكر واجهة ثنائية اللغة
A36: المنصة والأمن | B36: التقويم الهجري | C36: Hijri calendar | D36: 0 | E36: 0 | F36: 2 | G36: 0 | H36: 0 | I36: 0 | J36: 0 | K36: =COUNTIF(E36:J36,2) | L36: =IF(D36=2,"لا",IF(K36>=1,"نعم","نعم (ريادة محتملة)"))
A37: المنصة والأمن | B37: الرقابة الثنائية (Maker/Checker) على السجلات | C37: Maker-checker on records | D37: 1 | E37: 2 | F37: 2 | G37: 1 | H37: 2 | I37: 2 | J37: 0 | K37: =COUNTIF(E37:J37,2) | L37: =IF(D37=2,"لا",IF(K37>=1,"نعم","نعم (ريادة محتملة)")) | M37: لدينا: مراجعة RCSA ومنع المراجعة الذاتية فقط
A38: المنصة والأمن | B38: محرك سير عمل قابل للتهيئة وفصل المهام | C38: Configurable workflow engine / SoD | D38: 0 | E38: 2 | F38: 2 | G38: 1 | H38: 2 | I38: 2 | J38: 0 | K38: =COUNTIF(E38:J38,2) | L38: =IF(D38=2,"لا",IF(K38>=1,"نعم","نعم (ريادة محتملة)"))
A39: المنصة والأمن | B39: تنبيهات بريد/رسائل نصية وتصعيد تلقائي | C39: Email/SMS alerts and auto-escalation | D39: 0 | E39: 2 | F39: 2 | G39: 2 | H39: 2 | I39: 1 | J39: 0 | K39: =COUNTIF(E39:J39,2) | L39: =IF(D39=2,"لا",IF(K39>=1,"نعم","نعم (ريادة محتملة)")) | M39: لدينا: لا بريد إلكتروني إطلاقاً
A40: المنصة والأمن | B40: إدارة المهام والتقويم وصفحة «مهامي» | C40: Task management, calendar, "my tasks" | D40: 0 | E40: 1 | F40: 1 | G40: 2 | H40: 1 | I40: 1 | J40: 0 | K40: =COUNTIF(E40:J40,2) | L40: =IF(D40=2,"لا",IF(K40>=1,"نعم","نعم (ريادة محتملة)"))
...

Sheet POC check
A1: # | B1: الخطوة | C1: Step | D1: الحالة (F/P/M) | E1: ملاحظة
A2: 1 | B2: حدث خسارة | C2: Loss event | D2: F | E2: تسجيل كامل بالإجمالي والمستردات والصافي
A3: 2 | B3: السبب الجذري | C3: Root cause | D3: P | E3: حقل نصي إلزامي للإغلاق؛ بلا تصنيف أسباب
A4: 3 | B4: RCSA | C4: RCSA | D4: P | E4: استبيان ومراجعة؛ بلا جدولة ولا ضوابط داخل التقييم
A5: 4 | B5: اختبار الضوابط | C5: Control test | D5: M | E5: غير موجود
A6: 5 | B6: الخطر المتبقي | C6: Residual risk | D6: F | E6: صريح مع مبررات وفئات
A7: 6 | B7: خطة المعالجة | C7: Action plan | D7: F | E7: مع مسؤول وموعد وحالة وتأخر
A8: 7 | B8: خرق KRI | C8: KRI breach | D8: P | E8: حالة وتنبيه على الشاشة؛ بلا سجل خرق ولا بريد
A9: 8 | B9: التصعيد | C9: Escalation | D9: M | E9: لا تصعيد آلي
A10: 9 | B10: لوحة المجلس | C10: Board dashboard | D10: F | E10: خرائط حرارة ومؤشرات؛ بلا حزمة PDF للمجلس
A11: 10 | B11: واجهة عربية | C11: Arabic UI | D11: F
A12: 11 | B12: AD/SSO | C12: AD/SSO | D12: M | E12: غير موجود
A13: 12 | B13: Maker/Checker | C13: Maker/Checker | D13: P | E13: RCSA فقط
A14: 13 | B14: رفع الأدلة | C14: Evidence upload | D14: F | E14: مع فحص المحتوى وحفظ خارج الجذر العام
A15: 14 | B15: سجل التدقيق | C15: Audit trail | D15: F
A16: 15 | B16: استدعاء API | C16: API call | D16: M | E16: غير موجود
A17: 16 | B17: تصدير PDF/Excel | C17: Export PDF/Excel | D17: P | E17: CSV وطباعة PDF من المتصفح؛ لا XLSX/PDF أصلي
A18: 17 | B18: دور ضابط ارتباط الفرع | C18: Branch Risk Liaison role | D18: F | E18: مع تقييد البيانات بالفرع
B20: مغطى كلياً (F) | D20: =COUNTIF(D2:D18,"F")
B21: جزئي (P) | D21: =COUNTIF(D2:D18,"P")
B22: مفقود (M) | D22: =COUNTIF(D2:D18,"M")
B23: نسبة التغطية الكاملة | D23: =D20/COUNTA(D2:D18)

Sheet Practices
A1: الممارسة / المعيار | B1: المضمون | C1: ما يعنيه لمنصتنا | D1: بنود الخطة | E1: المصدر
A2: اتفاقية بازل: المبادئ المنقّحة لإدارة المخاطر التشغيلية (2021) | B2: 12 مبدأً: الحوكمة، بيئة إدارة المخاطر (تحديد وتقييم، إدارة التغيير، المتابعة والإبلاغ، الرقابة والتخفيف)، تقنية المعلومات، استمرارية الأعمال، الإفصاح. | C2: الضوابط واختبارها، إدارة التغيير (محفّزات التقييم)، ICT، BCP | D2: GRC-001/002/012/015/016 | E2: https://www.bis.org/bcbs/publ/d515.htm
A3: بازل: مبادئ المرونة التشغيلية (2021) | B3: قدرة المصرف على الصمود والتكيف والتعافي: الخدمات الحرجة، خرائط الاعتماديات، حدود تحمل الانقطاع، اختبار السيناريوهات، الأطراف الثالثة. | C3: وحدة BIA/BCP كاملة وحدود التحمل والأطراف الثالثة | D3: GRC-015/016/017/029 | E3: https://www.bis.org/bcbs/publ/d516.pdf
A4: IFSB-1: إدارة المخاطر للمؤسسات المقدِّمة للخدمات المالية الإسلامية | B4: مخاطر خاصة: عدم الالتزام الشرعي، مخاطر معدل العائد، الاستثمار بالمشاركة، التجارة المنقولة، ومخاطر تشغيلية. | C4: لدينا الفئات؛ ينقص تقييم ومؤشرات متخصصة | D4: GRC-020/021 | E4: https://islamic-banking.com/ifsb-standards/
A5: IFSB-10 ومعايير AAOIFI للحوكمة: الحوكمة الشرعية | B5: هيئة رقابة شرعية، مراجعة/تدقيق شرعي داخلي، تقرير الالتزام الشرعي. | C5: وحدة الامتثال الشرعي (فجوة لا يغطيها أي عرض) | D5: GRC-020 | E5: https://www.ifsb.org/press-releases/the-ifsb-publishes-four-new-frequently-asked-questions-faqs-on-key-standards/
A6: IFSB-15 (كفاية رأس المال) وIFSB-30 (الحوكمة المؤسسية) | B6: معايير احترازية مشتقة من بازل للمصارف الإسلامية؛ IFSB-30 مبادئ حوكمة منقحة. | C6: حوكمة المجلس واللجان؛ رأس المال خارج النطاق | D6: GRC-022/035 | E6: https://www.ifsb.org/wp-content/uploads/2023/10/ED-30_En.pdf
A7: ساما (السعودية): إطار الحوكمة الشرعية وإدارة المخاطر للمصرفية المتوافقة مع الشريعة | B7: توقعات رقابية على وظيفة الامتثال الشرعي وإدارة مخاطر الائتمان والسوق والتشغيل والسيولة والاستثمار بالأسهم. | C7: مثال إقليمي لوحدة شرعية مدمجة بإدارة المخاطر | D7: GRC-020/021 | E7: https://rulebook.sama.gov.sa/en/shariah-governance-framework-local-banks-operating-saudi-arabia
A8: مصرف الإمارات المركزي: لائحة المخاطر التشغيلية | B8: تربط المخاطر التشغيلية والمرونة بالحوكمة والضوابط والتقنية وإدارة التغيير والأطراف الثالثة (تاريخ السريان المذكور في نتيجة البحث: 14 سبتمبر 2026؛ يلزم التحقق من النص الرسمي). | C8: دمج التشغيلي والمرونة والأطراف الثالثة | D8: GRC-015/029 | E8: https://grc2020.com/2026/09/27/the-uaes-grc-market-ambition-meets-the-resilience-test/
A9: مصرف ليبيا المركزي: مدونة الحوكمة للقطاع المصرفي (2010) ودليل الحوكمة (التعميم 19 لسنة 2024) | B9: لجان المجلس (التدقيق، المكافآت، المخاطر، الحوكمة) ومبادئ إدارة مخاطر الائتمان والسوق والتشغيل والسيولة والسلوك. لم أستطع فتح صفحة المصرف المركزي (محجوبة)؛ المعلومة من ملخص بحث ويجب التحقق من التعميم الأصلي. | C9: حوكمة اللجان والتزام التشكيل والاجتماعات | D9: GRC-022 | E9: https://cbl.gov.ly/en/central-bank-of-libya-issues-comprehensive-banking-sector-governance-manual/
A10: ISO 31000 / COSO ERM | B10: ربط المخاطر بالاستراتيجية والأداء وقابلية تحمل المخاطر. | C10: أهداف استراتيجية وقابلية المخاطر والقبول بصلاحيات | D10: GRC-011/022 | E10: -
A11: BCBS 239 (تجميع بيانات المخاطر والإبلاغ) | B11: جودة البيانات، الاكتمال، التوقيت، الأصل البياني للإبلاغ. | C11: بوابة جودة بيانات KRI، نموذج بيانات موحد | D11: GRC-008/024 | E11: -
A12: سوق منصات GRC/IRM | B12: المنصات الكبرى تركّز على تنسيق سير العمل عبر المخاطر والامتثال والأطراف الثالثة والمرونة؛ وغارتنر لم تعد تعتبر IRM سوقاً مستقلاً بل GRC. | C12: محرك سير عمل ووحدات مترابطة بنموذج بيانات واحد | D12: GRC-004/005 | E12: https://www.marketsandmarkets.com/ResearchInsight/enterprise-governance-risk-compliance-market.asp

Sheet Vendor notes
A1: المورد | B1: ملاحظة تستحق المتابعة قبل الترسية
A2: Rabbit-Hole | B2: يذكر المقترح (ص16) أن وحدة BCM «قيد البناء»، بينما تصنّف مقارنة اللجنة BCM لديه «قوي». يلزم تثبيت كتابي للجاهزية قبل الترسية.
A3: Rabbit-Hole | B3: مخطط البنية وقاموس البيانات ملكية فكرية لدى المورد (ص20)، والتكامل غير مشمول في السعر، وربط الدفعات 20/30/40/10%. تأكد من الحق في تصدير البيانات عند الخروج.
A4: FOCUS | B4: تعارض في رسوم الصيانة داخل العرض (15,000 مقابل 12,600) كما أشارت اللجنة؛ ومتطلبات خوادم Windows/IIS/.NET و MS SQL و16GB/1TB على عاتق المصرف.
A5: SHIRA | B5: قسم كبير استشاري؛ الترخيص «دائم/لمدة التعاقد» (ص24) يحتاج توضيحاً؛ ربط KRI/KPI الآلي يحتاج جهداً برمجياً يُقدَّر لاحقاً (ص28). ورقة العرض تمنع إطلاع طرف ثالث دون موافقة كتابية.
A6: Shamil | B6: منصة تطوير مخصصة (Spring Boot/React/Keycloak/Camunda) وليست منتجاً جاهزاً: النتيجة «بناء مخصص» بسقف 5–6 أشهر وملكية مشتركة للشيفرة؛ مواصفاته الوظيفية الأغنى (RCSA/خسائر/KRI/BCM/ESG) هي الأفضل مرجعاً لمتطلباتنا.
A7: OneSumX | B7: 5 مستخدمين مسمّين فقط، زيادة سنوية CPI+1% لعقد 5 سنوات، والسفر والضرائب خارج السعر؛ تفاصيل KRI «أقل بروزاً» في العرض نفسه.
A8: Ocean/ITS | B8: عرض استشاري بلا منصة (200 ألف دولار) وتاريخه 31/08/2025 وصلاحيته 30 يوماً، أي أنه منتهي الصلاحية ما لم يُجدَّد؛ مناسب لمسار IT/Cyber GRC منفصل.
A9: عام | B9: لم يصف أي من العروض وحدة امتثال شرعي (قرارات/تدقيق/عدم التزام/تطهير)؛ هذا متطلب فريد للمصرف الإسلامي يمكن أن تتميز به منصتنا.

Sheet Sources
A1: المصدر | B1: الرابط / ملاحظة
A2: العروض الفنية والمالية الستة وملف جو جلوبال ولوحة مقارنة اللجنة | B2: مرفوعة من المستخدم — تُقرأ كما وردت دون تحقق مستقل من ادعاءات الموردين
A3: BIS: Revisions to PSMOR (2021) | B3: https://www.bis.org/bcbs/publ/d515.htm
A4: BIS: Principles for Operational Resilience (2021) | B4: https://www.bis.org/bcbs/publ/d516.pdf
A5: IFSB standards overview | B5: https://islamic-banking.com/ifsb-standards/
A6: SAMA Shariah Governance Framework | B6: https://rulebook.sama.gov.sa/en/shariah-governance-framework-local-banks-operating-saudi-arabia
A7: SAMA Risk Management for Shariah Compliant Banking | B7: https://rulebook.sama.gov.sa/en/entiresection/10190
A8: CBUAE operational risk (via GRC2020 article) | B8: https://grc2020.com/2026/09/27/the-uaes-grc-market-ambition-meets-the-resilience-test/
A9: Central Bank of Libya — Banking Supervision / governance manual | B9: https://cbl.gov.ly/en/banking-supervision/ (الصفحة محجوبة من بيئتي؛ المعلومة من ملخص بحث)
A10: GRC/IRM market overview (MarketsandMarkets) | B10: https://www.marketsandmarkets.com/ResearchInsight/enterprise-governance-risk-compliance-market.asp
